Workbook

Sheet README
A1: Yield Intelligence — Opportunity Catalog
A3: Purpose
A4: This is the comprehensive catalog of opportunity types Yield Intelligence can detect and recommend across customer engagements. It exists to: (1) define the universe of recommendations the product will generate, (2) provide a shared reference for product, design, and engineering teams, (3) ensure the product's intelligence layer is grounded in realistic strategic options.
A6: Coverage
A7: 94 opportunities across 9 categories. Multi-vertical applicability (Retail / B2B SaaS / DTC / Services). Spans tactical day-to-day optimization through board-level strategic moves.
A9: How to use this document
A10: • Open the 'Catalog' sheet for the master list. All columns are filterable.
A11: • Use the 'Vertical applicability' sheet to filter opportunities by industry vertical.
A12: • Use the 'Summary' sheet to see distribution counts and identify gaps.
A13: • Use the 'Field reference' sheet to understand what each column means.
A14: • Update the 'Status' column to track team review (Proposed / Validated / Needs review / Cut).
A16: Categories
... A88: 3. CX_LIFT effects on LTV — should they flow into main portfolio ROI display or stay in a dedicated LTV/CAC panel?

Sheet Catalog
A1: ID | B1: Category | C1: Subcategory | D1: Opportunity name | E1: Description | F1: Magnitude — Low ($) | G1: Magnitude — High ($) | H1: Mag band | I1: Confidence | J1: Required data signals | K1: External signals used | L1: Timeline | M1: Reversibility | N1: Decision audience | O1: Retail | P1: B2B SaaS | Q1: DTC | R1: Services | S1: Trigger conditions | T1: Risk notes | U1: Status | V1: Effects (JSON) | W1: Impl one-time ($K) | X1: Impl annual ($K) | Y1: Impl timing | Z1: Dependencies | AA1: Mutex with | AB1: Requires signals | AC1: Schema review status
A2: OPP-001 | B2: Tactical | C2: Reallocation | D2: Shift budget from saturated channel to channel with headroom | E2: Move spend from a channel at/past its marginal-ROI inflection point into a channel with positive marginal ROI gap. Most common high-confidence move. | F2: 50000 | G2: 1000000 | H2: L | I2: H | J2: MMM marginal-ROI curves; channel saturation flags; spend history | K2: Industry CPM benchmarks (validate target channel pricing) | L2: Days | M2: H | N2: Marketing Ops | O2: Y | P2: Y | Q2: Y | R2: Y | S2: Channel A marginal ROI < portfolio median AND Channel B marginal ROI > 1.5× threshold AND headroom confirmed | T2: Cannibalization risk between channels touching same audience; estimated via Shapley overlap | U2: Proposed | V2: [{"type":"spend_shift", "from_channel":"saturated", "amount_k":300, "to_channel":"headroom"}] | Y2: immediate | AB2: industry_cpm_benchmarks | AC2: auto-high
A3: OPP-002 | B3: Tactical | C3: Scale | D3: Increase spend on top-decile campaign within healthy channel | E3: Identified campaigns showing above-average ROI AND positive marginal returns AND stable trend. Scale aggressively while conditions hold. | F3: 20000 | G3: 500000 | H3: M | I3: H | J3: Campaign-level ROI; marginal ROI; 30-day trend stability | K3: Industry CPM benchmarks; demand signals (search trend) | L3: Days | M3: H | N3: Marketing Ops | O3: Y | P3: Y | Q3: Y | R3: Y | S3: Campaign ROI > channel median × 1.3 AND marginal ROI > 2× AND no declining trend | T3: Diminishing returns set in faster than modeled if competitor enters; recheck weekly | U3: Proposed | V3: [{"type":"spend_shift", "from_channel":"portfolio_reserve", "amount_k":150, "to_channel":"top_decile_campaign"}] | Y3: immediate | AB3: industry_cpm_benchmarks, search_trend_data | AC3: auto-high
A4: OPP-003 | B4: Tactical | C4: Cut | D4: Eliminate sub-1× ROI campaign at zero downside | E4: Campaign returning less than its spend over 90+ days with no improvement trajectory. Cut and redeploy. Lowest-risk move in the catalog. | F4: 10000 | G4: 250000 | H4: M | I4: H | J4: Campaign 90-day ROI < 1.0; trend slope ≥ 0; no recent creative refresh | K4: None — internal data sufficient | L4: Days | M4: H | N4: Marketing Ops | O4: Y | P4: Y | Q4: Y | R4: Y | S4: ROI < 1.0× over 90 days AND trend not improving AND not in protected campaign list | T4: Audience signal loss for prospecting funnel; check downstream channel impact | U4: Proposed | V4: [{"type":"spend_shift", "from_channel":"losing_channel", "amount_k":200, "to_channel":null}] | Y4: immediate | AC4: auto-high
A5: OPP-004 | B5: Tactical | C5: Cap spend | D5: Cap spend on past-peak campaign to halt overinvestment | E5: Campaign past saturation point — additional spend yields diminishing or negative marginal returns. Cap at current level rather than cut entirely. | F5: 20000 | G5: 600000 | H5: M | I5: H | J5: Marginal ROI < 1.0 at current spend; spend trend rising | K5: None — internal data sufficient | L5: Days | M5: H | N5: Marketing Ops | O5: Y | P5: Y | Q5: Y | R5: Y | S5: Marginal ROI declining for 4+ consecutive weeks AND total ROI still > 1× AND spend > median | T5: Need to monitor — partial cap may push budget to even worse alternative | U5: Proposed | V5: [{"type":"spend_shift", "from_channel":"past_peak_channel", "amount_k":150, "to_channel":null}] | Y5: immediate | AC5: auto-high
A6: OPP-005 | B6: Tactical | C6: Audience refinement | D6: Narrow targeting on broad-audience campaign to lift CVR | E6: Broad audience campaigns showing wide CVR variance. Tighten to top-quartile audience segments to lift portfolio efficiency. | F6: 5000 | G6: 150000 | H6: M | I6: M | J6: Audience-level CVR data; audience overlap matrix; segment performance | K6: First-party CRM enrichment (if available) | L6: Days | M6: H | N6: Marketing Ops | O6: Y | P6: Y | Q6: Y | R6: Y | S6: Audience-level CVR variance > 3× AND top quartile has sufficient volume | T6: Reduces reach; may need supplementary prospecting elsewhere | U6: Proposed | V6: [{"type":"curve_shift", "channel":"target_channel", "shift_type":"multiplicative", "shift_magnitude":1.08, "ramp_months":1, "confidence_range":[1.04, 1.12]}] | Y6: immediate | AC6: auto-medium
A7: OPP-006 | B7: Tactical | C7: Creative refresh | D7: Refresh fatigued creative on declining campaign | E7: Campaign showing declining CTR + flat-to-rising CPM = creative fatigue signal. Refresh before performance deteriorates further. | F7: 5000 | G7: 80000 | H7: S | I7: M | J7: CTR trend; CPM trend; days since last creative variant | K7: Competitive promotional intelligence (what's running in market) | L7: Weeks | M7: H | N7: Marketing Ops | O7: Y | P7: Y | Q7: Y | R7: Y | S7: CTR declining > 15% over 30 days AND no creative refresh in 60+ days | T7: Refresh may need 2-3 cycles; budget for testing variants | U7: Proposed | V7: [{"type":"curve_shift", "channel":"fatigued_channel", "shift_type":"multiplicative", "shift_magnitude":1.1, "ramp_months":1, "confidence_range":[1.05, 1.15]}] | Y7: immediate | AB7: competitor_promotional_intel | AC7: auto-medium
A8: OPP-007 | B8: Tactical | C8: Frequency cap | D8: Apply frequency cap to over-served retargeting audience | E8: Retargeting frequency above industry threshold (typically 5-7/week) without proportional conversion lift. Apply cap to reduce waste. | F8: 10000 | G8: 200000 | H8: M | I8: M | J8: Retargeting frequency distribution; CVR by frequency band | K8: Industry frequency benchmarks | L8: Days | M8: H | N8: Marketing Ops | O8: Y | P8: Y | Q8: Y | R8: Y | S8: Avg frequency > 8/week AND CVR doesn't improve above frequency 5 | T8: Can hurt completion-rate metrics for view-through attribution | U8: Proposed | V8: [{"type":"spend_shift", "from_channel":"over_served_retargeting", "amount_k":80, "to_channel":null}, {"type":"curve_shift", "channel":"retargeting_channel", "shift_type":"multiplicative", "shift_magnitude":1.05, "ramp_months":1, "confidence_range":[1.02, 1.08]}] | Y8: immediate | AC8: auto-high
A9: OPP-008 | B9: Tactical | C9: Bid strategy change | D9: Switch bid strategy to better match objective | E9: Campaign optimizing for wrong objective (e.g., max-clicks when conversions are countable). Switch to target-CPA or value-based bidding. | F9: 5000 | G9: 100000 | H9: M | I9: M | J9: Conversion volume; current bid strategy; tCPA feasibility check | K9: None — internal data sufficient | L9: Days | M9: H | N9: Marketing Ops | O9: Y | P9: Y | Q9: Y | R9: Y | S9: Sufficient conversion volume (50+/month) AND current strategy mismatched to goal | T9: Initial 2-week learning period may show worse short-term performance | U9: Proposed | V9: [{"type":"curve_shift", "channel":"target_channel", "shift_type":"multiplicative", "shift_magnitude":1.08, "ramp_months":1, "confidence_range":[1.03, 1.13]}] | Y9: immediate | AC9: auto-medium
A10: OPP-009 | B10: Tactical | C10: Day-parting | D10: Restrict spend to high-conversion hours/days | E10: Conversion data shows strong day/hour patterns. Restrict spend to high-converting windows to lift portfolio CVR. | F10: 5000 | G10: 75000 | H10: S | I10: M | J10: Hourly/daily conversion patterns; sufficient time-series data | K10: Macro indicator data (consumer activity patterns) | L10: Days | M10: H | N10: Marketing Ops | O10: Y | P10: P | Q10: Y | R10: Y | S10: CVR varies > 40% across hours/days AND consistent pattern over 60+ days | T10: Reduced reach may push CPMs higher in tight windows | U10: Proposed | V10: [{"type":"curve_shift", "channel":"target_channel", "shift_type":"multiplicative", "shift_magnitude":1.06, "ramp_months":1, "confidence_range":[1.03, 1.1]}] | Y10: immediate | AB10: macro_indicators | AC10: auto-medium
A11: OPP-010 | B11: Tactical | C11: Geo adjustment | D11: Shift spend toward high-LTV geographies | E11: Customer LTV varies meaningfully by geography. Shift acquisition spend toward geos with above-portfolio LTV. | F11: 20000 | G11: 400000 | H11: M | I11: M | J11: Customer LTV by geo; current spend distribution by geo | K11: Macro indicators (regional economic conditions) | L11: Weeks | M11: H | N11: Marketing Ops | O11: Y | P11: Y | Q11: Y | R11: Y | S11: LTV variance by geo > 1.5× AND current spend not proportionally weighted | T11: Geo concentration risk; consider keeping floor in lower-LTV geos | U11: Proposed | V11: [{"type":"curve_shift", "channel":"target_channel", "shift_type":"multiplicative", "shift_magnitude":1.08, "ramp_months":2, "confidence_range":[1.04, 1.12]}] | Y11: immediate | AB11: macro_indicators | AC11: auto-medium
A12: OPP-011 | B12: Tactical | C12: Landing page test | D12: A/B test landing page on high-traffic underperforming channel | E12: Channel with strong traffic but below-portfolio CVR. Test landing page variants to lift conversion rate at zero ad spend change. | F12: 10000 | G12: 60000 | H12: S | I12: M | J12: Channel traffic volume; CVR vs portfolio median; existing LP infrastructure | K12: None — internal data sufficient | L12: Weeks | M12: H | N12: Marketing Ops | O12: Y | P12: Y | Q12: Y | R12: Y | S12: Traffic > 5K visits/month AND CVR < portfolio median × 0.7 AND no recent LP test | T12: Test reads need 2-4 weeks for statistical significance | U12: Proposed | V12: [{"type":"cx_lift", "metric":"cvr", "lift_multiplier":1.05, "applies_to_channels":"all", "confidence_range":[1.02, 1.09], "ramp_months":1}] | Y12: immediate | AC12: auto-medium
A13: OPP-012 | B13: Tactical | C13: Promo timing | D13: Shift promo calendar to align with demand peaks | E13: Promotional offers running during low-demand periods. Realign to coincide with detected demand peaks for higher per-promo revenue. | F13: 10000 | G13: 200000 | H13: M | I13: M | J13: Conversion patterns; promo history; current calendar | K13: Calendar/seasonality data; demand signals (search trends) | L13: Weeks | M13: M | N13: Marketing Leadership | O13: Y | P13: P | Q13: Y | R13: Y | S13: Promos running during below-average demand windows AND high-demand windows have no promo | T13: Inventory and finance constraints on promo timing | U13: Proposed | V13: [{"type":"curve_shift", "channel":"target_channel", "shift_type":"multiplicative", "shift_magnitude":1.07, "ramp_months":1, "confidence_range":[1.03, 1.12]}] | Y13: immediate | AB13: search_trend_data, calendar_seasonality | AC13: auto-medium
A14: OPP-013 | B14: Tactical | C14: Search keyword expansion | D14: Add high-intent keyword variants to converting campaigns | E14: Existing keywords show high CVR but limited impression share. Expand keyword set with semantic variants and long-tail. | F14: 5000 | G14: 150000 | H14: M | I14: H | J14: Search Query Reports; impression share data; keyword CVR | K14: Search trend data (Google Trends/Semrush) | L14: Days | M14: H | N14: Marketing Ops | O14: Y | P14: Y | Q14: Y | R14: Y | S14: Top keywords have impression share < 70% AND CVR > campaign median | T14: Expansion may pull in lower-intent traffic; monitor CVR closely | U14: Proposed | V14: [{"type":"curve_shift", "channel":"target_search_channel", "shift_type":"multiplicative", "shift_magnitude":1.09, "ramp_months":1, "confidence_range":[1.05, 1.14]}] | Y14: immediate | AB14: search_trend_data | AC14: auto-medium
A15: OPP-014 | B15: Tactical | C15: Search keyword cuts | D15: Remove zero-conversion keywords from active campaigns | E15: Cleanup: identify and remove keywords with significant impressions/clicks but zero or near-zero conversions over 60+ days. | F15: 5000 | G15: 100000 | H15: M | I15: H | J15: Keyword-level conversion data; impressions; clicks | K15: None — internal data sufficient | L15: Days | M15: H | N15: Marketing Ops | O15: Y | P15: Y | Q15: Y | R15: Y | S15: Keyword has >100 clicks AND zero conversions over 60 days | T15: Some keywords serve brand/visibility purpose even if not converting | U15: Proposed | V15: [{"type":"spend_shift", "from_channel":"waste_keywords", "amount_k":50, "to_channel":null}] | Y15: immediate | AC15: auto-high
A16: OPP-015 | B16: Tactical | C16: Negative keyword expansion | D16: Add negative keywords to filter wasted impressions | E16: Search Query Report shows impressions on irrelevant queries. Add as negatives to reduce wasted spend. | F16: 2000 | G16: 50000 | H16: S | I16: H | J16: Search Query Reports across all search campaigns | K16: None — internal data sufficient | L16: Days | M16: H | N16: Marketing Ops | O16: Y | P16: Y | Q16: Y | R16: Y | S16: SQR shows >5% impression share on demonstrably irrelevant queries | T16: Risk of over-filtering; review weekly for first month | U16: Proposed | V16: [{"type":"curve_shift", "channel":"search_channel", "shift_type":"multiplicative", "shift_magnitude":1.04, "ramp_months":1, "confidence_range":[1.02, 1.07]}] | Y16: immediate | AC16: auto-medium
A17: OPP-016 | B17: Tactical | C17: Seasonal pre-positioning | D17: Pre-load spend ahead of forecasted demand peak | E17: Begin building auction presence and audience pools 2-4 weeks before known demand spike (BFCM, back-to-school, vertical-specific events). | F17: 50000 | G17: 800000 | H17: L | I17: H | J17: Forecasted demand calendar; auction CPM trends; historical lift data | K17: Calendar/seasonality; macro indicators | L17: Weeks | M17: M | N17: Marketing Leadership | O17: Y | P17: P | Q17: Y | R17: Y | S17: Demand peak in 2-6 weeks AND historical lift > 30% during window | T17: Cash-flow timing; CFO sign-off may be needed for early spend | U17: Proposed | V17: [{"type":"curve_shift", "channel":"target_channel", "shift_type":"multiplicative", "shift_magnitude":1.15, "ramp_months":1, "confidence_range":[1.08, 1.25]}] | Y17: immediate | AB17: macro_indicators, calendar_seasonality | AC17: auto-medium
A18: OPP-017 | B18: Tactical | C18: Campaign structure simplification | D18: Consolidate fragmented campaigns into structured set | E18: Account has accumulated 50+ small campaigns with overlapping audiences. Consolidate to enable algorithmic optimization at scale. | F18: 10000 | G18: 100000 | H18: M | I18: M | J18: Campaign count; audience overlap matrix; spend fragmentation | K18: None — internal data sufficient | L18: Weeks | M18: M | N18: Marketing Ops | O18: Y | P18: Y | Q18: Y | R18: Y | S18: >40 active campaigns AND median spend per campaign < $5K/month AND audience overlap > 30% | T18: Consolidation reduces granular reporting; may upset internal owners of cut campaigns | U18: Proposed | V18: [{"type":"curve_shift", "channel":"target_channel", "shift_type":"multiplicative", "shift_magnitude":1.06, "ramp_months":2, "confidence_range":[1.02, 1.1]}] | Y18: immediate | AC18: auto-medium
A19: OPP-018 | B19: Tactical | C19: Conversion event optimization | D19: Switch optimization event to higher-quality signal | E19: Campaign optimizing on top-of-funnel event (page view, add-to-cart) when value-event data is available. Switch for better algorithm signal. | F19: 5000 | G19: 100000 | H19: S | I19: M | J19: Conversion event configuration; value-event volume; current optimization target | K19: None — internal data sufficient | L19: Days | M19: H | N19: Marketing Ops | O19: Y | P19: Y | Q19: Y | R19: Y | S19: Value events > 50/month AND currently optimizing on lower-funnel proxy | T19: Algorithm relearning period; expect 2 weeks of variability | U19: Proposed | V19: [{"type":"curve_shift", "channel":"target_channel", "shift_type":"multiplicative", "shift_magnitude":1.08, "ramp_months":1, "confidence_range":[1.04, 1.13]}] | Y19: immediate | AC19: auto-medium
A20: OPP-019 | B20: Tactical | C20: Cross-channel exclusion | D20: Exclude converted customers from prospecting audiences | E20: Customers who recently converted are still in prospecting audience pools. Exclude to reduce wasted impressions. | F20: 10000 | G20: 200000 | H20: M | I20: H | J20: CRM customer list; ad platform custom audience setup; current exclusion config | K20: None — internal data sufficient | L20: Weeks | M20: H | N20: Marketing Ops | O20: Y | P20: Y | Q20: Y | R20: Y | S20: No active converted-customer exclusion AND high-frequency retargeting overlap | T20: Need clean CRM-to-platform sync; data privacy compliance check | U20: Proposed | V20: [{"type":"curve_shift", "channel":"prospecting_channel", "shift_type":"multiplicative", "shift_magnitude":1.05, "ramp_months":1, "confidence_range":[1.03, 1.08]}] | Y20: immediate | AC20: auto-medium
A21: OPP-020 | B21: Tactical | C21: Bid modifier adjustment | D21: Apply device/audience/time bid modifiers to align with value | E21: Performance varies meaningfully by device, audience segment, or daypart but bidding is uniform. Apply modifiers to improve efficiency. | F21: 5000 | G21: 100000 | H21: S | I21: M | J21: Performance breakdowns by device, audience, time | K21: None — internal data sufficient | L21: Days | M21: H | N21: Marketing Ops | O21: Y | P21: Y | Q21: Y | R21: Y | S21: Performance variance > 2× across one or more dimensions AND current bid modifiers near 0% | T21: Modifier interactions complex; test incrementally | U21: Proposed | V21: [{"type":"curve_shift", "channel":"target_channel", "shift_type":"multiplicative", "shift_magnitude":1.06, "ramp_months":1, "confidence_range":[1.03, 1.1]}] | Y21: immediate | AC21: auto-medium
A22: OPP-021 | B22: Strategic-Channel | C22: New channel test | D22: Launch CTV/streaming TV testing on Hulu/Roku/Pluto | E22: Currently zero CTV presence in mix. Industry data shows category fit + audience overlap. Test budget to validate before scaling. | F22: 250000 | G22: 800000 | H22: L | I22: M | J22: Current channel mix; audience profile; brand creative readiness | K22: Industry CPM benchmarks (CTV pricing); competitor spend estimates; demand signals | L22: Quarters | M22: M | N22: CMO | O22: Y | P22: P | Q22: Y | R22: P | S22: Customer audience over-indexes on streaming AND no CTV presence AND test budget available | T22: Measurement attribution for CTV is harder; need view-through methodology | U22: Proposed | V22: [{"type":"new_channel", "channel_id":"ctv", "channel_name":"Connected TV", "test_spend_k":400, "peak_marginal_roi":2.8, "saturation_k":1200, "confidence":"medium", "ramp_months":3}] | W22: 40 | Y22: 2 weeks setup | AB22: industry_cpm_benchmarks, competitor_promotional_intel | AC22: auto-medium
A23: OPP-022 | B23: Strategic-Channel | C23: New channel test | D23: Add Reddit advertising for community-engaged audiences | E23: Reddit has emerged as high-intent platform for tech, finance, gaming, hobby verticals. Test on relevant subreddits for audience match. | F23: 50000 | G23: 200000 | H23: M | I23: M | J23: Audience profile; brand suitability for Reddit context | K23: Industry CPM benchmarks; competitive promotional intelligence | L23: Months | M23: M | N23: Marketing Leadership | O23: P | P23: Y | Q23: Y | R23: P | S23: Audience over-indexes on Reddit AND brand voice can adapt to platform AND no current presence | T23: Reddit moderator dynamics; brand safety; community backlash risk | U23: Proposed | V23: [{"type":"new_channel", "channel_id":"reddit", "channel_name":"Reddit", "test_spend_k":100, "peak_marginal_roi":2.5, "saturation_k":350, "confidence":"medium", "ramp_months":2}] | W23: 40 | Y23: 2 weeks setup | AB23: industry_cpm_benchmarks, competitor_promotional_intel | AC23: auto-medium
A24: OPP-023 | B24: Strategic-Channel | C24: New channel test | D24: Launch TikTok creator partnerships and paid | E24: TikTok delivers high reach for younger demos. Combination of organic creator content + paid amplification works better than pure paid. | F24: 100000 | G24: 500000 | H24: L | I24: M | J24: Audience age profile; brand creative production capability | K24: Industry CPM benchmarks; competitor spend estimates; demand signals | L24: Months | M24: M | N24: Marketing Leadership | O24: Y | P24: P | Q24: Y | R24: P | S24: Target audience skews under 35 AND creative team can produce TikTok-native content | T24: Platform algorithm changes frequently; creator relationship management overhead | U24: Proposed | V24: [{"type":"new_channel", "channel_id":"tiktok", "channel_name":"TikTok", "test_spend_k":200, "peak_marginal_roi":2.6, "saturation_k":700, "confidence":"medium", "ramp_months":2}] | W24: 40 | Y24: 2 weeks setup | AB24: industry_cpm_benchmarks, competitor_promotional_intel | AC24: auto-medium
A25: OPP-024 | B25: Strategic-Channel | C25: New channel test | D25: Add podcast advertising for trust-building reach | E25: Podcast ads deliver high attention and trust. Host-read formats work especially well for considered purchases. | F25: 75000 | G25: 300000 | H25: L | I25: M | J25: Audience podcast consumption; consideration cycle length | K25: Industry CPM benchmarks (podcast inventory); competitor spend | L25: Months | M25: M | N25: Marketing Leadership | O25: Y | P25: Y | Q25: Y | R25: Y | S25: Considered purchase (>$200 ASP or B2B) AND audience consumes podcasts | T25: Attribution challenges; need promo-code or branded survey approach | U25: Proposed | V25: [{"type":"new_channel", "channel_id":"podcast", "channel_name":"Podcast", "test_spend_k":150, "peak_marginal_roi":2.4, "saturation_k":500, "confidence":"medium", "ramp_months":3}] | W25: 40 | Y25: 2 weeks setup | AB25: industry_cpm_benchmarks, competitor_promotional_intel | AC25: auto-medium
A26: OPP-025 | B26: Strategic-Channel | C26: New channel test | D26: Add OOH/DOOH in high-density target markets | E26: Out-of-home advertising for brand-building in priority geos. Programmatic DOOH (digital OOH) enables data-targeted placement. | F26: 150000 | G26: 600000 | H26: L | I26: L | J26: Geographic concentration; brand-equity gap in target markets | K26: Industry CPM benchmarks; competitor activity | L26: Quarters | M26: L | N26: CMO | O26: Y | P26: Y | Q26: Y | R26: Y | S26: Brand awareness gap in priority geos AND budget for awareness investment | T26: Hard to attribute lift; long lead time for placements | U26: Proposed | V26: [{"type":"new_channel", "channel_id":"ooh", "channel_name":"Out-of-home", "test_spend_k":300, "peak_marginal_roi":2.2, "saturation_k":900, "confidence":"low", "ramp_months":3}] | W26: 40 | Y26: 2 weeks setup | AB26: industry_cpm_benchmarks, competitor_promotional_intel | AC26: auto-medium
A27: OPP-026 | B27: Strategic-Channel | C27: New channel test | D27: Launch Pinterest for visual/lifestyle categories | E27: Pinterest delivers strong intent for home, fashion, beauty, food, wedding categories. Lower competition than Meta in many verticals. | F27: 30000 | G27: 200000 | H27: M | I27: M | J27: Product category fit; visual content library | K27: Industry CPM benchmarks; demand signals | L27: Months | M27: M | N27: Marketing Leadership | O27: Y | P27: P | Q27: Y | R27: N | S27: Product is visually-driven AND target audience female-skewed | T27: Audience skew may not match B2B or technical products | U27: Proposed | V27: [{"type":"new_channel", "channel_id":"pinterest", "channel_name":"Pinterest", "test_spend_k":80, "peak_marginal_roi":2.8, "saturation_k":350, "confidence":"medium", "ramp_months":2}] | W27: 40 | Y27: 2 weeks setup | AB27: industry_cpm_benchmarks | AC27: auto-medium
A28: OPP-027 | B28: Strategic-Channel | C28: Geographic expansion | D28: Open international markets where organic demand exists | E28: Detect geographies with significant organic traffic but no targeted spend. Activate paid acquisition in those markets. | F28: 200000 | G28: 800000 | H28: L | I28: H | J28: Geographic traffic distribution; conversion rates by geo; payment/fulfillment readiness | K28: Macro indicators (target market economics); demand signals | L28: Quarters | M28: M | N28: CMO | O28: Y | P28: Y | Q28: Y | R28: P | S28: >15% organic traffic from non-targeted geos AND fulfillment infrastructure ready | T28: Localization, currency, tax, returns, customer support requirements | U28: Proposed | V28: [{"type":"new_channel", "channel_id":"international", "channel_name":"International markets", "test_spend_k":300, "peak_marginal_roi":2.8, "saturation_k":900, "confidence":"medium", "ramp_months":3}] | W28: 40 | Y28: 2 weeks setup | AB28: macro_indicators | AC28: auto-medium
A29: OPP-028 | B29: Strategic-Channel | C29: Audience expansion | D29: Open new customer segment (B2B / SMB / Enterprise) | E29: Detected demand from segment outside current targeting. Build dedicated funnel and acquisition motion. | F29: 200000 | G29: 1500000 | H29: XL | I29: M | J29: Cross-segment lead/customer signals; product-market fit indicators for new segment | K29: Industry segment data; competitor activity in segment | L29: Quarters | M29: L | N29: CMO | O29: Y | P29: Y | Q29: P | R29: Y | S29: Inbound demand from non-targeted segment AND product features support segment AND ICP definition possible | T29: Segment may require different product positioning, pricing, sales motion | U29: Proposed | V29: [{"type":"new_channel", "channel_id":"new_segment", "channel_name":"New customer segment", "test_spend_k":400, "peak_marginal_roi":2.6, "saturation_k":1200, "confidence":"low", "ramp_months":6}] | W29: 40 | Y29: 2 weeks setup | AB29: competitor_promotional_intel | AC29: auto-medium
A30: OPP-029 | B30: Strategic-Channel | C30: Owned media | D30: Launch newsletter/content engine for owned audience growth | E30: Build first-party audience asset less subject to platform algorithm risk. Long payback but compounding asset. | F30: 150000 | G30: 400000 | H30: L | I30: M | J30: Current owned-media presence; audience growth rate | K30: Industry benchmarks for newsletter ROI; demand signals (topic interest) | L30: Quarters | M30: M | N30: Marketing Leadership | O30: Y | P30: Y | Q30: Y | R30: Y | S30: Heavy dependence on paid AND audience demonstrates appetite for educational content | T30: Long ramp; needs sustained editorial investment; team capability question | U30: Proposed | V30: [{"type":"new_channel", "channel_id":"owned_media", "channel_name":"Owned media", "test_spend_k":150, "peak_marginal_roi":3.5, "saturation_k":500, "confidence":"low", "ramp_months":6}] | W30: 40 | Y30: 2 weeks setup | AC30: auto-medium
A31: OPP-030 | B31: Strategic-Channel | C31: Owned media | D31: Launch branded podcast or YouTube channel | E31: Build owned video/audio audience for brand building, thought leadership, and SEO benefit. | F31: 200000 | G31: 600000 | H31: L | I31: L | J31: Audience consumption habits; brand voice strength | K31: Demand signals (topic interest); competitor activity | L31: Quarters | M31: L | N31: CMO | O31: Y | P31: Y | Q31: Y | R31: Y | S31: Strong subject matter expertise in-house AND audience consumes long-form content | T31: Production cost; consistency required (12+ months); attribution unclear | U31: Proposed | V31: [{"type":"new_channel", "channel_id":"owned_media", "channel_name":"Owned media", "test_spend_k":150, "peak_marginal_roi":3.5, "saturation_k":500, "confidence":"low", "ramp_months":6}] | W31: 40 | Y31: 2 weeks setup | AB31: competitor_promotional_intel | AC31: auto-medium
A32: OPP-031 | B32: Strategic-Channel | C32: Partnership | D32: Build affiliate/partner program | E32: Activate channel of partners (creators, complementary brands, publishers) with revenue-share structure. Performance-based, lower CAC ceiling. | F32: 50000 | G32: 400000 | H32: L | I32: M | J32: Partner ecosystem maturity; product fit for partnership; tracking infrastructure | K32: Industry partnership benchmarks; competitor partner programs | L32: Quarters | M32: M | N32: Marketing Leadership | O32: Y | P32: Y | Q32: Y | R32: Y | S32: Identifiable partner pool AND product fits partnership economics AND tracking ready | T32: Partner quality control; brand safety; payment reconciliation overhead | U32: Proposed | V32: [{"type":"new_channel", "channel_id":"partner_channel", "channel_name":"Partner/affiliate", "test_spend_k":100, "peak_marginal_roi":3.2, "saturation_k":400, "confidence":"medium", "ramp_months":3}] | W32: 40 | Y32: 2 weeks setup | AB32: competitor_promotional_intel | AC32: auto-medium
A33: OPP-032 | B33: Strategic-Channel | C33: Partnership | D33: Launch creator/influencer program | E33: Move from one-off creator deals to managed program. Build creator portfolio aligned with brand and audience. | F33: 100000 | G33: 500000 | H33: L | I33: M | J33: Audience overlap with creators; current ad-hoc spend; brand creative guidelines | K33: Industry creator economy data; competitor creator activity | L33: Quarters | M33: M | N33: Marketing Leadership | O33: Y | P33: P | Q33: Y | R33: P | S33: Audience consumes creator content AND brand can adapt to creator-led messaging | T33: Creator vetting; FTC/disclosure compliance; performance variance | U33: Proposed | V33: [{"type":"new_channel", "channel_id":"partner_channel", "channel_name":"Partner/affiliate", "test_spend_k":100, "peak_marginal_roi":3.2, "saturation_k":400, "confidence":"medium", "ramp_months":3}] | W33: 40 | Y33: 2 weeks setup | AB33: competitor_promotional_intel | AC33: auto-medium
A34: OPP-033 | B34: Strategic-Channel | C34: Partnership | D34: Activate co-marketing with complementary brand | E34: Partner with non-competing brand serving same customer for joint campaigns, content, audience swaps. Shared cost, expanded reach. | F34: 30000 | G34: 300000 | H34: L | I34: M | J34: Customer overlap analysis; partner brand identification | K34: Competitor activity; demand signals | L34: Months | M34: M | N34: Marketing Leadership | O34: Y | P34: Y | Q34: Y | R34: Y | S34: Identified non-competing brand with audience overlap AND mutual interest | T34: Partner alignment difficult to maintain; brand safety risk | U34: Proposed | V34: [{"type":"new_channel", "channel_id":"partner_channel", "channel_name":"Partner/affiliate", "test_spend_k":100, "peak_marginal_roi":3.2, "saturation_k":400, "confidence":"medium", "ramp_months":3}] | W34: 40 | Y34: 2 weeks setup | AB34: competitor_promotional_intel | AC34: auto-medium
A35: OPP-034 | B35: Strategic-Channel | C35: Niche publication | D35: Add niche B2B/vertical publication advertising | E35: Industry-specific publications deliver high-fit audience at lower CPM than mass platforms. Especially valuable for B2B and considered purchases. | F35: 50000 | G35: 300000 | H35: L | I35: M | J35: Audience read-list; ICP overlap with publication audience | K35: Industry CPM benchmarks; publication audience data | L35: Months | M35: M | N35: Marketing Leadership | O35: P | P35: Y | Q35: P | R35: Y | S35: B2B or considered purchase AND identifiable vertical publications AND audience overlap | T35: Limited scale; manual placement workflows | U35: Proposed | V35: [{"type":"new_channel", "channel_id":"niche_pub", "channel_name":"Niche publication", "test_spend_k":80, "peak_marginal_roi":2.9, "saturation_k":300, "confidence":"medium", "ramp_months":2}] | W35: 40 | Y35: 2 weeks setup | AB35: industry_cpm_benchmarks | AC35: auto-medium
A36: OPP-035 | B36: Strategic-Channel | C36: Native advertising | D36: Launch native/content distribution | E36: Distribute brand content via native ad networks (Outbrain, Taboola, Nativo) for top-funnel awareness with content-format engagement. | F36: 80000 | G36: 400000 | H36: L | I36: M | J36: Content asset library; brand voice adaptability | K36: Industry CPM benchmarks; competitor spend | L36: Months | M36: M | N36: Marketing Leadership | O36: Y | P36: Y | Q36: Y | R36: Y | S36: Content library exists AND awareness gap AND budget for top-funnel investment | T36: Native quality varies; brand safety; attribution challenges | U36: Proposed | V36: [{"type":"new_channel", "channel_id":"native", "channel_name":"Native advertising", "test_spend_k":150, "peak_marginal_roi":2.3, "saturation_k":500, "confidence":"medium", "ramp_months":2}] | W36: 40 | Y36: 2 weeks setup | AB36: industry_cpm_benchmarks, competitor_promotional_intel | AC36: auto-medium
A37: OPP-036 | B37: Strategic-Capability | C37: In-housing | D37: Build in-house creative team for paid social | E37: Agency creative cycle is bottlenecking iteration. In-housing reduces cycle time from weeks to days, enabling test-and-learn at platform speed. | F37: 250000 | G37: 600000 | H37: L | I37: M | J37: Current creative cycle time; volume of creative requests; agency cost | K37: Industry agency vs in-house benchmarks; talent market data | L37: Quarters | M37: L | N37: CMO | O37: Y | P37: Y | Q37: Y | R37: Y | S37: Agency cycle time > 2 weeks AND creative request volume justifies team AND budget for hiring | T37: Hiring risk; capability gaps; need for senior leadership | U37: Proposed | V37: [{"type":"curve_shift", "channel":"meta-pros", "shift_type":"multiplicative", "shift_magnitude":1.15, "ramp_months":6, "confidence_range":[1.08, 1.22]}, {"type":"curve_shift", "channel":"meta-rt", "shift_type":"multiplicative", "shift_magnitude":1.12, "ramp_months":6, "confidence_range":[1.06, 1.18]}] | W37: 80 | X37: 380 | Y37: 6-month ramp | AC37: auto-medium
A38: OPP-037 | B38: Strategic-Capability | C38: In-housing | D38: Bring media buying in-house | E38: Eliminate agency markup on programmatic and platform media buying. Requires team, tooling, and platform certifications. | F38: 400000 | G38: 1500000 | H38: XL | I38: L | J38: Current agency fees; media spend volume; team capability assessment | K38: Industry in-housing benchmarks; talent market data | L38: Quarters | M38: L | N38: CMO | O38: Y | P38: Y | Q38: Y | R38: Y | S38: Media spend > $5M AND agency fees > 8% of spend AND in-house capability buildable | T38: Major undertaking; 12-18 month transition; requires CFO + executive support | U38: Proposed | V38: [{"type":"cost_reduction", "source":"agency_fees", "annual_savings_k":600, "one_time_cost_k":200, "realization_months":12}, {"type":"curve_shift", "channel":"meta-pros", "shift_type":"multiplicative", "shift_magnitude":1.08, "ramp_months":9, "confidence_range":[1.04, 1.12]}] | W38: 80 | X38: 380 | Y38: 6-month ramp | AC38: auto-medium
A39: OPP-038 | B39: Strategic-Capability | C39: In-housing | D39: Build in-house analytics/MMM team | E39: Replace external analytics vendor with internal team for faster turnaround, better data integration, lower long-term cost. | F39: 200000 | G39: 500000 | H39: L | I39: M | J39: Current analytics spend; data infrastructure maturity; internal capability | K39: Industry analytics function benchmarks | L39: Quarters | M39: L | N39: CMO | O39: Y | P39: Y | Q39: P | R39: P | S39: Analytics spend > $300K/year AND data infrastructure mature AND need for faster cycles | T39: Specialist hiring difficult; tool/platform investment alongside team | U39: Proposed | V39: [{"type":"cost_reduction", "source":"tool_subscription", "annual_savings_k":180, "one_time_cost_k":100, "realization_months":9}] | W39: 80 | X39: 380 | Y39: 6-month ramp | AC39: auto-medium
A40: OPP-039 | B40: Strategic-Capability | C40: Tech stack | D40: Implement Customer Data Platform (CDP) | E40: Unify customer data across channels and systems. Enables better targeting, personalization, attribution. Major foundational investment. | F40: 200000 | G40: 800000 | H40: L | I40: M | J40: Current data architecture; system count; identity resolution gaps | K40: Industry CDP vendor data; benchmarks | L40: Quarters | M40: L | N40: CMO | O40: Y | P40: Y | Q40: Y | R40: Y | S40: 5+ disconnected customer data systems AND identity resolution issues AND personalization opportunity | T40: Implementation complexity; vendor lock-in; ongoing maintenance | U40: Proposed | V40: [{"type":"cx_lift", "metric":"cvr", "lift_multiplier":1.08, "applies_to_channels":"all", "confidence_range":[1.04, 1.12], "ramp_months":6}] | W40: 120 | X40: 100 | Y40: 4-month implementation | AC40: auto-medium
...

Sheet Vertical applicability
A1: ID | B1: Opportunity name | C1: Category | D1: Retail | E1: B2B SaaS | F1: DTC | G1: Services
A2: =Catalog!A2 -> OPP-001 | B2: =Catalog!D2 -> Shift budget from saturated channel to channel with headroom | C2: =Catalog!B2 -> Tactical | D2: =Catalog!O2 -> Y | E2: =Catalog!P2 -> Y | F2: =Catalog!Q2 -> Y | G2: =Catalog!R2 -> Y
A3: =Catalog!A3 -> OPP-002 | B3: =Catalog!D3 -> Increase spend on top-decile campaign within healthy channel | C3: =Catalog!B3 -> Tactical | D3: =Catalog!O3 -> Y | E3: =Catalog!P3 -> Y | F3: =Catalog!Q3 -> Y | G3: =Catalog!R3 -> Y
A4: =Catalog!A4 -> OPP-003 | B4: =Catalog!D4 -> Eliminate sub-1× ROI campaign at zero downside | C4: =Catalog!B4 -> Tactical | D4: =Catalog!O4 -> Y | E4: =Catalog!P4 -> Y | F4: =Catalog!Q4 -> Y | G4: =Catalog!R4 -> Y
A5: =Catalog!A5 -> OPP-004 | B5: =Catalog!D5 -> Cap spend on past-peak campaign to halt overinvestment | C5: =Catalog!B5 -> Tactical | D5: =Catalog!O5 -> Y | E5: =Catalog!P5 -> Y | F5: =Catalog!Q5 -> Y | G5: =Catalog!R5 -> Y
A6: =Catalog!A6 -> OPP-005 | B6: =Catalog!D6 -> Narrow targeting on broad-audience campaign to lift CVR | C6: =Catalog!B6 -> Tactical | D6: =Catalog!O6 -> Y | E6: =Catalog!P6 -> Y | F6: =Catalog!Q6 -> Y | G6: =Catalog!R6 -> Y
A7: =Catalog!A7 -> OPP-006 | B7: =Catalog!D7 -> Refresh fatigued creative on declining campaign | C7: =Catalog!B7 -> Tactical | D7: =Catalog!O7 -> Y | E7: =Catalog!P7 -> Y | F7: =Catalog!Q7 -> Y | G7: =Catalog!R7 -> Y
A8: =Catalog!A8 -> OPP-007 | B8: =Catalog!D8 -> Apply frequency cap to over-served retargeting audience | C8: =Catalog!B8 -> Tactical | D8: =Catalog!O8 -> Y | E8: =Catalog!P8 -> Y | F8: =Catalog!Q8 -> Y | G8: =Catalog!R8 -> Y
A9: =Catalog!A9 -> OPP-008 | B9: =Catalog!D9 -> Switch bid strategy to better match objective | C9: =Catalog!B9 -> Tactical | D9: =Catalog!O9 -> Y | E9: =Catalog!P9 -> Y | F9: =Catalog!Q9 -> Y | G9: =Catalog!R9 -> Y
A10: =Catalog!A10 -> OPP-009 | B10: =Catalog!D10 -> Restrict spend to high-conversion hours/days | C10: =Catalog!B10 -> Tactical | D10: =Catalog!O10 -> Y | E10: =Catalog!P10 -> P | F10: =Catalog!Q10 -> Y | G10: =Catalog!R10 -> Y
A11: =Catalog!A11 -> OPP-010 | B11: =Catalog!D11 -> Shift spend toward high-LTV geographies | C11: =Catalog!B11 -> Tactical | D11: =Catalog!O11 -> Y | E11: =Catalog!P11 -> Y | F11: =Catalog!Q11 -> Y | G11: =Catalog!R11 -> Y
A12: =Catalog!A12 -> OPP-011 | B12: =Catalog!D12 -> A/B test landing page on high-traffic underperforming channel | C12: =Catalog!B12 -> Tactical | D12: =Catalog!O12 -> Y | E12: =Catalog!P12 -> Y | F12: =Catalog!Q12 -> Y | G12: =Catalog!R12 -> Y
A13: =Catalog!A13 -> OPP-012 | B13: =Catalog!D13 -> Shift promo calendar to align with demand peaks | C13: =Catalog!B13 -> Tactical | D13: =Catalog!O13 -> Y | E13: =Catalog!P13 -> P | F13: =Catalog!Q13 -> Y | G13: =Catalog!R13 -> Y
... A95: =Catalog!A95 -> OPP-094 | B95: =Catalog!D95 -> Marketing turnaround following major performance decline | C95: =Catalog!B95 -> Strategic-Meta | D95: =Catalog!O95 -> Y | E95: =Catalog!P95 -> Y | F95: =Catalog!Q95 -> Y | G95: =Catalog!R95 -> Y

Sheet Summary
A1: Catalog summary
A3: By category
A4: Category | B4: Count
A5: Tactical | B5: =COUNTIF(Catalog!B:B,"Tactical") -> 20
A6: Strategic-Channel | B6: =COUNTIF(Catalog!B:B,"Strategic-Channel") -> 15
A7: Strategic-Capability | B7: =COUNTIF(Catalog!B:B,"Strategic-Capability") -> 16
A8: Strategic-Cost | B8: =COUNTIF(Catalog!B:B,"Strategic-Cost") -> 9
A9: Strategic-CX | B9: =COUNTIF(Catalog!B:B,"Strategic-CX") -> 10
A10: Strategic-Pricing | B10: =COUNTIF(Catalog!B:B,"Strategic-Pricing") -> 4
A11: Strategic-Measurement | B11: =COUNTIF(Catalog!B:B,"Strategic-Measurement") -> 5
A12: Strategic-Content | B12: =COUNTIF(Catalog!B:B,"Strategic-Content") -> 4
A13: Strategic-Meta | B13: =COUNTIF(Catalog!B:B,"Strategic-Meta") -> 3
A14: Defensive | B14: =COUNTIF(Catalog!B:B,"Defensive") -> 8
A15: TOTAL | B15: =SUM(B5:B14) -> 94
A18: By magnitude
A19: Band | B19: Count
A20: S (under $50K) | B20: =COUNTIF(Catalog!H:H,"S") -> 7
A21: M ($50K–$250K) | B21: =COUNTIF(Catalog!H:H,"M") -> 41
A22: L ($250K–$1M) | B22: =COUNTIF(Catalog!H:H,"L") -> 40
A23: XL (over $1M) | B23: =COUNTIF(Catalog!H:H,"XL") -> 6
A25: By confidence
A26: Band | B26: Count
A27: High (>85%) | B27: =COUNTIF(Catalog!I:I,"H") -> 24
A28: Medium (70–85%) | B28: =COUNTIF(Catalog!I:I,"M") -> 60
A29: Low (<70%) | B29: =COUNTIF(Catalog!I:I,"L") -> 10
A31: By decision audience
A32: Audience | B32: Count
A33: Board/CEO | B33: =COUNTIF(Catalog!N:N,"Board/CEO") -> 2
A34: CFO | B34: =COUNTIF(Catalog!N:N,"CFO") -> 4
A35: CMO | B35: =COUNTIF(Catalog!N:N,"CMO") -> 28
A36: CMO/CEO | B36: =COUNTIF(Catalog!N:N,"CMO/CEO") -> 1
A37: CMO/CFO | B37: =COUNTIF(Catalog!N:N,"CMO/CFO") -> 1
A38: Legal/CMO | B38: =COUNTIF(Catalog!N:N,"Legal/CMO") -> 1
A39: Marketing Leadership | B39: =COUNTIF(Catalog!N:N,"Marketing Leadership") -> 38
A40: Marketing Ops | B40: =COUNTIF(Catalog!N:N,"Marketing Ops") -> 19
A43: Vertical applicability (count of 'Y' opportunities)
A44: Vertical | B44: Primary fit (Y) | C44: Partial fit (P)
A45: Retail | B45: =COUNTIF(Catalog!O:O,"Y") -> 91 | C45: =COUNTIF(Catalog!O:O,"P") -> 3
A46: B2B SaaS | B46: =COUNTIF(Catalog!P:P,"Y") -> 76 | C46: =COUNTIF(Catalog!P:P,"P") -> 16
A47: DTC | B47: =COUNTIF(Catalog!Q:Q,"Y") -> 88 | C47: =COUNTIF(Catalog!Q:Q,"P") -> 6
...

Sheet Field reference
A1: Field reference
A3: Field | B3: Definition
A4: ID | B4: Unique identifier (OPP-001 through OPP-094). Used to reference opportunities in product code and across docs.
A5: Category | B5: Top-level grouping. 9 strategic categories + 1 tactical + 1 defensive.
A6: Subcategory | B6: More specific type within category. Helps with detail-page templating.
A7: Opportunity name | B7: The recommendation in plain English, as a CMO would say it.
A8: Description | B8: 2-3 sentences explaining what the move is and why it matters.
A9: Magnitude — Low ($) | B9: Lower bound of typical dollar impact for a customer in our $10M–$200M marketing org range.
A10: Magnitude — High ($) | B10: Upper bound of typical dollar impact.
A11: Mag band | B11: Band: S (<$50K), M ($50K–$250K), L ($250K–$1M), XL (>$1M).
A12: Confidence | B12: Typical model confidence: H (>85%), M (70–85%), L (<70%). Strategic moves with limited historical analogue tend to be lower.
A13: Required data signals | B13: What internal data the system needs to detect or evaluate this opportunity.
A14: External signals used | B14: Which of the 5 external signal types this opportunity uses: Industry CPM/CPC benchmarks, Search trend data, Macro indicators, Calendar/seasonality, Competitor promotional intelligence.
... A29: Schema review status | B29: Confidence of the first-pass spec. auto-high = review briefly; auto-medium = review normally; auto-low = review carefully; empty = must define manually; team-validated = approved.

Sheet Schema reference
A1: Channel-impact schema reference
A3: The five effect types
A4: Type | B4: Purpose | C4: Key fields
A5: spend_shift | B5: Move money between channels | C5: from_channel, to_channel (or null), amount_k
A6: curve_shift | B6: Modify marginal-ROI curve shape for a channel | C6: channel, shift_type, shift_magnitude, ramp_months, confidence_range
A7: new_channel | B7: Add a channel not currently in the mix | C7: channel_id, channel_name, test_spend_k, peak_marginal_roi, saturation_k, confidence, ramp_months
A8: cost_reduction | B8: Reduce total spend without changing channel curves | C8: source, annual_savings_k, one_time_cost_k, realization_months
A9: cx_lift | B9: Lift revenue per conversion (CVR/AOV/LTV) | C9: metric, lift_multiplier, applies_to_channels, confidence_range, ramp_months
A12: Review status values
A13: Value | B13: Meaning | C13: Review priority
A14: auto-high | B14: Spec generated from a strong pattern (tactical SPEND_SHIFT, COST_REDUCTION) — defaults are reasonable | C14: Review briefly
A15: auto-medium | B15: Spec generated from a reasonable heuristic but numbers need validation (new channels, capability changes) | C15: Review normally
A16: auto-low | B16: Spec is a rough estimate — portfolio-level curve shifts for measurement/defensive ops are educated guesses | C16: Review carefully
A17: empty | B17: No spec generated — category/subcategory didn't match any generator | C17: Must define manually
A18: team-validated | B18: After team review. Use this to mark specs the team has approved | C18: n/a
A22: External signal IDs
A23: Signal ID | B23: Description
A24: industry_cpm_benchmarks | B24: eMarketer / WordStream-style CPM and CPC benchmarks per channel and vertical
A25: search_trend_data | B25: Google Trends API + Semrush for demand signal validation
A26: macro_indicators | B26: Fed data, consumer confidence index — macro context for spend timing
A27: calendar_seasonality | B27: Seasonality patterns, vertical-specific events (BFCM, back-to-school, etc.)
A28: competitor_promotional_intel | B28: Competitor price/promo scraping + spend estimates (SimilarWeb, Pathmatics)
A29: industry_cpm_ctv | B29: CTV-specific CPM benchmarks (sub-signal of industry_cpm_benchmarks)
A30: competitor_ctv_spend | B30: Competitor CTV spend estimates (sub-signal of competitor_promotional_intel)
A33: Composition algorithm (summary)
A34: 1. Start with baseline (9 channels with current curves, $8.40M spend, $30.19M revenue)
A35: 2. Apply NEW_CHANNEL effects — add new curves to portfolio
A36: 3. Apply CURVE_SHIFT effects — modify affected channel curves (multiplicative composition when multiple hit same channel)
A37: 4. Apply SPEND_SHIFT effects + slider adjustments — compute new per-channel spend vector
A38: 5. Compute channel revenues via integral of curves
A39: 6. Apply CX_LIFT effects — multiply total revenue by (1 + weighted CX lifts)
A40: 7. Apply COST_REDUCTION effects — subtract annual_savings from spend denominator
A41: 8. Compute portfolio ROI, CAC, marginal ROI, etc.
